Workbook
Name A_impresión_IM: #REF!
Name ANNUAL_OTHER_TAX: [1]Assumptions!$B$48
Name ANNUAL_PERS_PROPERTY_TAX: [1]Assumptions!$B$47
Name ANNUAL_REAL_PROPERTY_TAX: [1]Assumptions!$B$46
Name AVG_NO_EMPLOYEES: [1]Assumptions!$B$74
Name BUDGET_YEAR: [1]Assumptions!$B$4
Name CELL_PHONE_100: [1]Assumptions!$B$35
Name CELL_PHONE_50: [1]Assumptions!$B$34
Name CLEANING_MINS_PER_ROOM: [1]Assumptions!$B$27
Name COST_OF_BEER: [1]Assumptions!$B$155
Name COST_OF_BEVERAGE: [1]Assumptions!$B$154
Name COST_OF_FOOD: [1]Assumptions!$B$152
Name COST_OF_LIQUOR: [1]Assumptions!$B$156
Name COST_OF_PREPACKAGED: [1]Assumptions!$B$153
Name COST_OF_WINE: [1]Assumptions!$B$157
Name CREDIT_CARD_COMMISSION_RATE: [1]Assumptions!$B$12
Name DATE_REV_FIGURES: [1]Assumptions!$B$7
Name Demand2Data: #REF!
Name Demand2Date2: #REF!
Name Demand2Metric: #REF!
Name EMPLOYEE_BENEFITS: [1]Assumptions!$F$59
Name EMPLOYEE_ONBOARDING: [1]Assumptions!#REF!
Name EMPLOYEE_TRAINING: [1]Assumptions!$B$32
Name ESDG_FACTOR: [1]Assumptions!$B$16
Name ESDG_PER_STAY: [1]Assumptions!$B$17
Name FAIR_TRADE_PRICING: [1]Assumptions!$B$14
Name FechaDeInicioelañoFiscal: '[2]FLUJO DE EFECTIVO'!$B$7
Name FEE_ACCOUNTING: [1]Assumptions!$B$38
Name FEE_BACKGROUND_CHECK: [1]Assumptions!$B$33
Name FEE_MANAGEMENT: [1]Assumptions!$B$8
Name FEE_MARKETING_BRAND: [1]Assumptions!$B$11
Name FEE_MARKETING_CENTRALIZED_SERVICES: [1]Assumptions!$B$41
Name FEE_REVMGMT_CENTRALIZED_SERVICES: [1]Assumptions!$B$39
Name FEE_ROYALTY_FB: [1]Assumptions!$B$10
Name FEE_ROYALTY_ROOMS: [1]Assumptions!$B$9
Name FEE_SALES_CENTRALIZED_SERVICES: [1]Assumptions!$B$40
Name FEE_TECHNOLOGY: [1]Assumptions!$B$37
Name FFE_RESERVE: [1]Assumptions!$B$13
Name HOTEL_NAME: [1]Assumptions!$B$2
Name MEMBERSHIP_COST_MULTIPLIER: #REF!
Name MEMBERSHIP_FEE_REVENUE: [1]Assumptions!$B$147
Name MINS_PER_HOUR: [1]Assumptions!$B$51
Name MONTHLY_INTERNET_SERVICE: [1]Assumptions!$B$43
Name MONTHLY_PHONE_SERVICE: [1]Assumptions!$B$44
Name MONTHLY_WASTE_REMOVAL: [1]Assumptions!$B$45
Name MY_FUNCTION1: _xludf.LAMBDA(SUM('[3]RATES CWL 2023-2024'!$B$48-500)/3)
Name MY_FUNCTION1: _xludf.LAMBDA(SUM('[3]RATES CWL 2023-2024'!$B$48-500)/3)
Name MY_FUNCTION1: _xludf.LAMBDA(SUM('[3]RATES CWL 2023-2024'!$B$48-500)/3)
Name MY_FUNCTION1: _xludf.LAMBDA(SUM('[3]RATES CWL 2023-2024'!$B$48-500)/3)
Name NO_OF_ROOMS: [1]Assumptions!$B$5
Name PAYROLL_TAXES: [1]Assumptions!$F$57
Name PET_FEE_MULTIPLIER: [1]Assumptions!$B$26
Name PET_FEE_PER_STAY: [1]Assumptions!$B$25
Name PRIOR_YEAR_TOTAL_OCCUPIED_ROOMS: Summary!$T$12
Name RESORT_FEE_MULTIPLIER: [1]Assumptions!$B$23
Name RESORT_FEE_PER_STAY: [1]Assumptions!$B$22
Name SUPPPAY: [1]Assumptions!$F$58
Name Tipo1: '[4]Tipo Cambio'!$1:$1048576
Name Tipo2: '[4]Tipo Cambio'!$1:$1
Name TOTAL_OCCUPIED_ROOMS: [1]Assumptions!$B$6

Sheet Summary
A1: Go to tabs: | B1: Rooms | C1: Food Revenue | D1: Beverage Revenue | E1: F&B Mis Revenue | F1: Spa Revenue | G1: Retail Gift Shop | H1: Activities | I1: Transportation | J1: Innoceanna | K1: Sustainability Fee | L1: Laundry
A3: Enter 2026 monthly budget in B10:M10 of each tab. Summary pulls those cells.
B5: January | C5: February | D5: March | E5: April | F5: May | G5: June | H5: July | I5: August | J5: September | K5: October | L5: November | M5: December | N5: TOTAL
A7: 2026 Revenue Budget – Summary
A9: Key Indicators 2026 (Budget) | B9: January | C9: February | D9: March | E9: April | F9: May | G9: June | H9: July | I9: August | J9: September | K9: October | L9: November | M9: December | N9: TOTAL
A10: Indicator
A12: Total available Rooms | B12: =+Rooms!C27 -> 930 | C12: =+Rooms!D27 -> 840 | D12: =+Rooms!E27 -> 930 | E12: =+Rooms!F27 -> 900 | F12: =+Rooms!G27 -> 930 | G12: =+Rooms!H27 -> 900 | H12: =+Rooms!I27 -> 930 | I12: =+Rooms!J27 -> 930 | ... N12: =+Rooms!O27 -> 10020 | O12: =+N46 -> 10950 | P12: =+N12+O12 -> 20970
A13: Total Rooms Occupied | B13: =+Rooms!C28 -> 697.5 | C13: =+Rooms!D28 -> 638.4 | D13: =+Rooms!E28 -> 607.7 | E13: =+Rooms!F28 -> 332 | F13: =+Rooms!G28 -> 232.48621 | G13: =+Rooms!H28 -> 167.65517 | H13: =+Rooms!I28 -> 332.1 | I13: =+Rooms!J28 -> 251.32 | ... N13: =+Rooms!O28 -> 4363.2889 | O13: =+N47 -> 3179
A14: Total Guests | B14: =+Rooms!C29 -> 1255.5 | C14: =+Rooms!D29 -> 1149.12 | D14: =+Rooms!E29 -> 1093.86 | E14: =+Rooms!F29 -> 597.6 | F14: =+Rooms!G29 -> 418.47517 | G14: =+Rooms!H29 -> 301.77931 | H14: =+Rooms!I29 -> 597.78 | I14: =+Rooms!J29 -> 452.376 | ... N14: =+Rooms!O29 -> 7853.92 | O14: =+N48 -> 5677
A15: % Occupancy | B15: =+Rooms!C30 -> 0.75 | C15: =+Rooms!D30 -> 0.76 | D15: =+Rooms!E30 -> 0.65344086 | E15: =+Rooms!F30 -> 0.36888889 | F15: =+Rooms!G30 -> 0.24998517 | G15: =+Rooms!H30 -> 0.18628352 | H15: =+Rooms!I30 -> 0.35709677 | I15: =+Rooms!J30 -> 0.27023656 | J15: =+Rooms!K30 -> 0.091466667 | L15: =+Rooms!M30 -> 0.45566667 | M15: =+Rooms!N30 -> 0.65775 | N15: =+Rooms!O30 -> 0.43545797 | O15: =+N49 -> 0.29031963 | P15: =+N15-O15 -> 0.14513834
A16: ADR | B16: =+Rooms!C31 -> 595.27155 | C16: =+Rooms!D31 -> 583.47405 | D16: =+Rooms!E31 -> 590.96203 | E16: =+Rooms!F31 -> 635.29075 | F16: =+Rooms!G31 -> 521.40328 | G16: =+Rooms!H31 -> 553.7017 | H16: =+Rooms!I31 -> 566.23141 | I16: =+Rooms!J31 -> 520.6179 | J16: =+Rooms!K31 -> 485.58682 | L16: =+Rooms!M31 -> 548.40744 | M16: =+Rooms!N31 -> 733.76344 | N16: =+Rooms!O31 -> 596.88852 | O16: =+N50 -> 484.67682 | P16: =+N16-O16 -> 112.2117 | Q16: =+P16/O16 -> 0.23151861
A18: Rooms | B18: =+Rooms!C38 -> 415201.91 | C18: =+Rooms!D38 -> 372489.83 | D18: =+Rooms!E38 -> 359127.63 | E18: =+Rooms!F38 -> 210916.53 | F18: =+Rooms!G38 -> 121219.07 | G18: =+Rooms!H38 -> 92830.953 | H18: =+Rooms!I38 -> 188045.45 | I18: =+Rooms!J38 -> 130841.69 | ... M18: =+Rooms!N38 -> 448848.6 | N18: =SUM(B18:M18) -> 2604397.1 | O18: =+N52 -> 1540787.6
A19: Food Revenue | B19: ='Food Revenue'!C38 -> 113356.58 | C19: ='Food Revenue'!D38 -> 103751.75 | D19: ='Food Revenue'!E38 -> 98762.432 | E19: ='Food Revenue'!F38 -> 53956.109 | F19: ='Food Revenue'!G38 -> 37783.286 | G19: ='Food Revenue'!H38 -> 27247.05 | H19: ='Food Revenue'!I38 -> 53972.361 | I19: ='Food Revenue'!J38 -> 40844.124 | ... M19: ='Food Revenue'!N38 -> 99413.724 | N19: =SUM(B19:M19) -> 709114.73 | O19: =+N53 -> 428040.29
A20: Beverage Revenue | B20: ='Beverage Revenue'!B38 -> 38541.239 | C20: ='Beverage Revenue'!C38 -> 35275.594 | D20: ='Beverage Revenue'!D38 -> 33579.227 | E20: ='Beverage Revenue'!E38 -> 18345.077 | F20: ='Beverage Revenue'!F38 -> 12846.317 | G20: ='Beverage Revenue'!G38 -> 9263.9971 | H20: ='Beverage Revenue'!H38 -> 18350.603 | I20: ='Beverage Revenue'!I38 -> 13887.002 | ... M20: ='Beverage Revenue'!M38 -> 33800.666 | N20: =SUM(B20:M20) -> 241099.01 | O20: =+N54 -> 136270.41
A21: F&B Mis Revenue | B21: ='F&B Mis Revenue'!B38 -> 0 | C21: ='F&B Mis Revenue'!C38 -> 0 | D21: ='F&B Mis Revenue'!D38 -> 0 | E21: ='F&B Mis Revenue'!E38 -> 0 | F21: ='F&B Mis Revenue'!F38 -> 0 | G21: ='F&B Mis Revenue'!G38 -> 0 | H21: ='F&B Mis Revenue'!H38 -> 0 | I21: ='F&B Mis Revenue'!I38 -> 0 | ... M21: ='F&B Mis Revenue'!M38 -> 0 | N21: =SUM(B21:M21) -> 0 | O21: =+N55 -> 33723.037
A22: Spa Revenue | B22: ='Spa Revenue'!B38 -> 5812.5 | C22: ='Spa Revenue'!C38 -> 5250 | D22: ='Spa Revenue'!D38 -> 5812.5 | E22: ='Spa Revenue'!E38 -> 5625 | F22: ='Spa Revenue'!F38 -> 5812.5 | G22: ='Spa Revenue'!G38 -> 5625 | H22: ='Spa Revenue'!H38 -> 5812.5 | I22: ='Spa Revenue'!I38 -> 5812.5 | ... M22: ='Spa Revenue'!M38 -> 5812.5 | N22: =SUM(B22:M22) -> 62625 | O22: =+N56 -> 32500.473
A23: Retail Gift Shop | B23: ='Retail Gift Shop'!B38 -> 4982.4229 | C23: ='Retail Gift Shop'!C38 -> 4469.878 | D23: ='Retail Gift Shop'!D38 -> 4309.5315 | E23: ='Retail Gift Shop'!E38 -> 2530.9984 | F23: ='Retail Gift Shop'!F38 -> 1454.6288 | G23: ='Retail Gift Shop'!G38 -> 1113.9714 | H23: ='Retail Gift Shop'!H38 -> 2256.5454 | I23: ='Retail Gift Shop'!I38 -> 1570.1003 | ... M23: ='Retail Gift Shop'!M38 -> 5386.1832 | N23: =SUM(B23:M23) -> 31252.765 | O23: =+N57 -> 18170.774
A24: Activities | B24: =Activities!B38 -> 106009.4 | C24: =Activities!C38 -> 97027.096 | D24: =Activities!D38 -> 92361.163 | E24: =Activities!E38 -> 50458.954 | F24: =Activities!F38 -> 35334.37 | G24: =Activities!G38 -> 25481.038 | H24: =Activities!H38 -> 50474.152 | I24: =Activities!I38 -> 38196.82 | ... M24: =Activities!M38 -> 92970.242 | N24: =SUM(B24:M24) -> 663153.59 | O24: =+N58 -> 303352.17 | P24: =+O26 -> 178974.46 | Q24: =+O24+P24 -> 482326.63 | R24: =+N24-Q24 -> 180826.96
A25: Transportation | B25: =Transportation!B38 -> 36735.93 | C25: =Transportation!C38 -> 33623.251 | D25: =Transportation!D38 -> 32006.344 | E25: =Transportation!E38 -> 17485.776 | F25: =Transportation!F38 -> 12244.584 | G25: =Transportation!G38 -> 8830.0626 | H25: =Transportation!H38 -> 17491.043 | I25: =Transportation!I38 -> 13236.522 | ... M25: =Transportation!M38 -> 32217.411 | N25: =SUM(B25:M25) -> 229805.7 | O25: =+N59 -> 121193.38
A26: Innoceanna | B26: =Innoceanna!B38 -> 2076.0095 | C26: =Innoceanna!C38 -> 1862.4492 | D26: =Innoceanna!D38 -> 1795.6381 | E26: =Innoceanna!E38 -> 1054.5827 | F26: =Innoceanna!F38 -> 606.09535 | G26: =Innoceanna!G38 -> 464.15477 | H26: =Innoceanna!H38 -> 940.22726 | I26: =Innoceanna!I38 -> 654.20846 | ... M26: =Innoceanna!M38 -> 2244.243 | N26: =SUM(B26:M26) -> 13021.985 | O26: =+N60 -> 178974.46
A27: Sustainability Fee | B27: ='Sustainability Fee'!B38 -> 35154 | C27: ='Sustainability Fee'!C38 -> 32175.36 | D27: ='Sustainability Fee'!D38 -> 30628.08 | E27: ='Sustainability Fee'!E38 -> 16732.8 | F27: ='Sustainability Fee'!F38 -> 11717.305 | G27: ='Sustainability Fee'!G38 -> 8449.8207 | H27: ='Sustainability Fee'!H38 -> 16737.84 | I27: ='Sustainability Fee'!I38 -> 12666.528 | ... M27: ='Sustainability Fee'!M38 -> 30830.058 | N27: =SUM(B27:M27) -> 219909.76 | O27: =+N61 -> 105632.78
A28: Laundry | B28: =Laundry!B38 -> 900 | C28: =Laundry!C38 -> 900 | D28: =Laundry!D38 -> 900 | E28: =Laundry!E38 -> 900 | F28: =Laundry!F38 -> 900 | G28: =Laundry!G38 -> 900 | H28: =Laundry!H38 -> 900 | I28: =Laundry!I38 -> 900 | ... M28: =Laundry!M38 -> 900 | N28: =SUM(B28:M28) -> 9900 | O28: =+N62 -> 6079.9388
A29: TOTAL REVENUE | B29: =SUM(B18:B28) -> 758769.99 | C29: =SUM(C18:C28) -> 686825.21 | D29: =SUM(D18:D28) -> 659282.54 | E29: =SUM(E18:E28) -> 378005.83 | F29: =SUM(F18:F28) -> 239918.16 | G29: =SUM(G18:G28) -> 180206.05 | H29: =SUM(H18:H28) -> 354980.72 | I29: =SUM(I18:I28) -> 258609.5 | ... O29: =SUM(O18:O28) -> 2904725.3 | P29: =(N29-O29)/O29 -> 0.64706782
A31: Hotel Package | B31: =+B18+B19+B24+B25+B27 -> 706457.82 | C31: =+C18+C19+C24+C25+C27 -> 639067.29 | D31: =+D18+D19+D24+D25+D27 -> 612885.64 | E31: =+E18+E19+E24+E25+E27 -> 349550.17 | F31: =+F18+F19+F24+F25+F27 -> 218298.61 | G31: =+G18+G19+G24+G25+G27 -> 162838.92 | H31: =+H18+H19+H24+H25+H27 -> 326720.85 | I31: =+I18+I19+I24+I25+I27 -> 235785.69 | ... N31: =+N18+N19+N24+N25+N27 -> 4426380.8
A32: Hotel Sales on Property | B32: =+B20+B22+B23+B26+B28 -> 52312.171 | C32: =+C20+C22+C23+C26+C28 -> 47757.921 | D32: =+D20+D22+D23+D26+D28 -> 46396.896 | E32: =+E20+E22+E23+E26+E28 -> 28455.658 | F32: =+F20+F22+F23+F26+F28 -> 21619.542 | G32: =+G20+G22+G23+G26+G28 -> 17367.123 | H32: =+H20+H22+H23+H26+H28 -> 28259.875 | I32: =+I20+I22+I23+I26+I28 -> 22823.811 | ... N32: =+N20+N22+N23+N26+N28 -> 357898.76
A34: Total | B34: =SUM(B31:B33) -> 758769.99 | C34: =SUM(C31:C33) -> 686825.21 | D34: =SUM(D31:D33) -> 659282.54 | E34: =SUM(E31:E33) -> 378005.83 | F34: =SUM(F31:F33) -> 239918.16 | G34: =SUM(G31:G33) -> 180206.05 | H34: =SUM(H31:H33) -> 354980.72 | I34: =SUM(I31:I33) -> 258609.5 | ... N34: =SUM(N31:N33) -> 4784279.6
A36: Relation Package and Property Sales | B36: =+B32/B31 -> 0.074048541 | C36: =+C32/C31 -> 0.074730661 | D36: =+D32/D31 -> 0.075702371 | E36: =+E32/E31 -> 0.081406506 | F36: =+F32/F31 -> 0.099036549 | G36: =+G32/G31 -> 0.10665216 | H36: =+H32/H31 -> 0.086495476 | I36: =+I32/I31 -> 0.096798968 | ... N36: =+N32/N31 -> 0.080855844
A38: Relation Rooms Only and Property Sales | B38: =+B32/B18 -> 0.12599213 | C38: =+C32/C18 -> 0.12821268 | D38: =+D32/D18 -> 0.12919334 | E38: =+E32/E18 -> 0.13491431 | F38: =+F32/F18 -> 0.17835099 | G38: =+G32/G18 -> 0.18708332 | H38: =+H32/H18 -> 0.15028215 | I38: =+I32/I18 -> 0.17443837 | ... N38: =+N32/N18 -> 0.13742097
A41: 2025 Revenue Forecast – Summary
A43: Key Indicators 2025 (Forecast) | B43: January | C43: February | D43: March | E43: April | F43: May | G43: June | H43: July | I43: August | J43: September | K43: October | L43: November | M43: December | N43: TOTAL
A44: Indicator
A46: Total available Rooms | B46: =+Rooms!C20 -> 930 | C46: =+Rooms!D20 -> 840 | D46: =+Rooms!E20 -> 930 | E46: =+Rooms!F20 -> 900 | F46: =+Rooms!G20 -> 930 | G46: =+Rooms!H20 -> 900 | H46: =+Rooms!I20 -> 930 | I46: =+Rooms!J20 -> 930 | J46: =+Rooms!K20 -> 900 | L46: =+Rooms!M20 -> 900 | M46: =+Rooms!N20 -> 930 | N46: =+Rooms!O20 -> 10950
A47: Total Rooms Occupied | B47: =+Rooms!C21 -> 454 | C47: =+Rooms!D21 -> 479 | D47: =+Rooms!E21 -> 519 | E47: =+Rooms!F21 -> 239 | F47: =+Rooms!G21 -> 114 | G47: =+Rooms!H21 -> 102 | H47: =+Rooms!I21 -> 274 | I47: =+Rooms!J21 -> 220 | J47: =+Rooms!K21 -> 28 | L47: =+Rooms!M21 -> 230 | M47: =+Rooms!N21 -> 470 | N47: =+Rooms!O21 -> 3179 | O47: =+N13-N47 -> 1184.2889 | P47: =+O47/N47 -> 0.37253504
A48: Total Guests | B48: =+Rooms!C22 -> 809 | C48: =+Rooms!D22 -> 893 | D48: =+Rooms!E22 -> 962 | E48: =+Rooms!F22 -> 428 | F48: =+Rooms!G22 -> 228 | G48: =+Rooms!H22 -> 183 | H48: =+Rooms!I22 -> 611 | I48: =+Rooms!J22 -> 411 | J48: =+Rooms!K22 -> 27 | L48: =+Rooms!M22 -> 345 | M48: =+Rooms!N22 -> 705 | N48: =+Rooms!O22 -> 5677 | O48: =+N14-N48 -> 2176.92 | P48: =+O48/N48 -> 0.38346309
A49: % Occupancy | B49: =+Rooms!C23 -> 0.48817204 | C49: =+Rooms!D23 -> 0.5702381 | D49: =+Rooms!E23 -> 0.55806452 | E49: =+Rooms!F23 -> 0.26555556 | F49: =+Rooms!G23 -> 0.12258065 | G49: =+Rooms!H23 -> 0.11333333 | H49: =+Rooms!I23 -> 0.29462366 | I49: =+Rooms!J23 -> 0.23655914 | J49: =+Rooms!K23 -> 0.031111111 | L49: =+Rooms!M23 -> 0.25555556 | M49: =+Rooms!N23 -> 0.50537634 | N49: =+Rooms!O23 -> 0.29031963 | O49: =+N15-N49 -> 0.14513834 | P49: =+O49/N49 -> 0.49992601
A50: ADR | B50: =+Rooms!C24 -> 473.50649 | C50: =+Rooms!D24 -> 550.00104 | D50: =+Rooms!E24 -> 478.48852 | E50: =+Rooms!F24 -> 497.89901 | F50: =+Rooms!G24 -> 482.76039 | G50: =+Rooms!H24 -> 379.47717 | H50: =+Rooms!I24 -> 508.05451 | I50: =+Rooms!J24 -> 371.59366 | J50: =+Rooms!K24 -> 402.95929 | L50: =+Rooms!M24 -> 405 | M50: =+Rooms!N24 -> 545 | N50: =+Rooms!O24 -> 484.67682 | O50: =+N16-N50 -> 112.2117 | P50: =+O50/N50 -> 0.23151861
A52: Rooms | B52: =+Rooms!C37 -> 214971.95 | C52: =+Rooms!D37 -> 263450.5 | D52: =+Rooms!E37 -> 248335.54 | E52: =+Rooms!F37 -> 118997.86 | F52: =+Rooms!G37 -> 55034.684 | G52: =+Rooms!H37 -> 38706.671 | H52: =+Rooms!I37 -> 139206.94 | I52: =+Rooms!J37 -> 81750.604 | ... M52: =+Rooms!N37 -> 256150 | N52: =SUM(B52:M52) -> 1540787.6
A53: Food Revenue | B53: ='Food Revenue'!C37 -> 55354.294 | C53: ='Food Revenue'!D37 -> 72196.172 | D53: ='Food Revenue'!E37 -> 70786.323 | E53: ='Food Revenue'!F37 -> 36330.097 | F53: ='Food Revenue'!G37 -> 16129.355 | G53: ='Food Revenue'!H37 -> 13689.425 | H53: ='Food Revenue'!I37 -> 46042.427 | I53: ='Food Revenue'!J37 -> 26588.885 | ... M53: ='Food Revenue'!N37 -> 55066.23 | N53: =SUM(B53:M53) -> 428040.29
A54: Beverage Revenue | B54: ='Beverage Revenue'!B37 -> 25207.195 | C54: ='Beverage Revenue'!C37 -> 20197.816 | D54: ='Beverage Revenue'!D37 -> 24274.211 | E54: ='Beverage Revenue'!E37 -> 12316.933 | F54: ='Beverage Revenue'!F37 -> 6154.7577 | G54: ='Beverage Revenue'!G37 -> 4103.4464 | H54: ='Beverage Revenue'!H37 -> 10937.432 | I54: ='Beverage Revenue'!I37 -> 10347.794 | ... M54: ='Beverage Revenue'!M37 -> 13766.558 | N54: =SUM(B54:M54) -> 136270.41
A55: F&B Mis Revenue | B55: ='F&B Mis Revenue'!B37 -> 0 | C55: ='F&B Mis Revenue'!C37 -> 0 | D55: ='F&B Mis Revenue'!D37 -> 0 | E55: ='F&B Mis Revenue'!E37 -> 0 | F55: ='F&B Mis Revenue'!F37 -> 0 | G55: ='F&B Mis Revenue'!G37 -> 0 | H55: ='F&B Mis Revenue'!H37 -> 33694.582 | I55: ='F&B Mis Revenue'!I37 -> 28.455862 | ... M55: ='F&B Mis Revenue'!M37 -> 0 | N55: =SUM(B55:M55) -> 33723.037
...

Sheet Rates 2026
C4: 46023 | D4: 46024 | E4: 46025 | F4: 46026 | G4: 46027 | H4: 46028 | I4: 46029 | J4: 46030 | K4: 46031 | L4: 46032 | M4: 46033 | N4: 46034
B6: Units Available | C6: 30 | D6: 30 | E6: 30 | F6: 30 | G6: 30 | H6: 30 | I6: 30 | J6: 30 | K6: 30 | L6: 30 | M6: 30 | N6: 30
B7: Day per month | C7: 31 | D7: 28 | E7: 31 | F7: 30 | G7: 31 | H7: 30 | I7: 31 | J7: 31 | K7: 30 | L7: 31 | M7: 30 | N7: 31
B9: Total Nights Available | C9: =+C6*C7 -> 930 | D9: =+D6*D7 -> 840 | E9: =+E6*E7 -> 930 | F9: =+F6*F7 -> 900 | G9: =+G6*G7 -> 930 | H9: =+H6*H7 -> 900 | I9: =+I6*I7 -> 930 | J9: =+J6*J7 -> 930 | ... N9: =+N6*N7 -> 930
B12: Units Category
A14: 1 | B14: Corcovado Deluxe Villas, King bed | C14: 6 | D14: 6 | E14: 6 | F14: 6 | G14: 6 | H14: 6 | I14: 6 | J14: 6 | K14: 6 | L14: 6 | M14: 6 | N14: 6
A15: 2 | B15: Carate Deluxe Villa Double Beds | C15: 2 | D15: 2 | E15: 2 | F15: 2 | G15: 2 | H15: 2 | I15: 2 | J15: 2 | K15: 2 | L15: 2 | M15: 2 | N15: 2
A16: 3 | B16: Agujas Villa 2 Queen Beds | C16: 4 | D16: 4 | E16: 4 | F16: 4 | G16: 4 | H16: 4 | I16: 4 | J16: 4 | K16: 4 | L16: 4 | M16: 4 | N16: 4
A17: 4 | B17: Sirena Suites, Queen Bed (conecting) | C17: 8 | D17: 8 | E17: 8 | F17: 8 | G17: 8 | H17: 8 | I17: 8 | J17: 8 | K17: 8 | L17: 8 | M17: 8 | N17: 8
A18: 5 | B18: Treehouse king bed | C18: 5 | D18: 5 | E18: 5 | F18: 5 | G18: 5 | H18: 5 | I18: 5 | J18: 5 | K18: 5 | L18: 5 | M18: 5 | N18: 5
A19: 6 | B19: 5 Elements Treehouse king bed | C19: 5 | D19: 5 | E19: 5 | F19: 5 | G19: 5 | H19: 5 | I19: 5 | J19: 5 | K19: 5 | L19: 5 | M19: 5 | N19: 5
B20: Total | C20: =SUM(C14:C19) -> 30 | D20: =SUM(D14:D19) -> 30 | E20: =SUM(E14:E19) -> 30 | F20: =SUM(F14:F19) -> 30 | G20: =SUM(G14:G19) -> 30 | H20: =SUM(H14:H19) -> 30 | I20: =SUM(I14:I19) -> 30 | J20: =SUM(J14:J19) -> 30 | ... N20: =SUM(N14:N19) -> 30
B23: Total Room Nights Available per Category
A25: 1 | B25: Corcovado Deluxe Villas, King bed | C25: =+C14*C$7 -> 186 | D25: =+D14*D$7 -> 168 | E25: =+E14*E$7 -> 186 | F25: =+F14*F$7 -> 180 | G25: =+G14*G$7 -> 186 | H25: =+H14*H$7 -> 180 | I25: =+I14*I$7 -> 186 | J25: =+J14*J$7 -> 186 | K25: =+K14*K$7 -> 180 | M25: =+M14*M$7 -> 180 | N25: =+N14*N$7 -> 186 | O25: =SUM(C25:N25) -> 2004
A26: 2 | B26: Carate Deluxe Villa Double Beds | C26: =+C15*C$7 -> 62 | D26: =+D15*D$7 -> 56 | E26: =+E15*E$7 -> 62 | F26: =+F15*F$7 -> 60 | G26: =+G15*G$7 -> 62 | H26: =+H15*H$7 -> 60 | I26: =+I15*I$7 -> 62 | J26: =+J15*J$7 -> 62 | K26: =+K15*K$7 -> 60 | M26: =+M15*M$7 -> 60 | N26: =+N15*N$7 -> 62 | O26: =SUM(C26:N26) -> 668
A27: 3 | B27: Agujas Villa 2 Queen Beds | C27: =+C16*C$7 -> 124 | D27: =+D16*D$7 -> 112 | E27: =+E16*E$7 -> 124 | F27: =+F16*F$7 -> 120 | G27: =+G16*G$7 -> 124 | H27: =+H16*H$7 -> 120 | I27: =+I16*I$7 -> 124 | J27: =+J16*J$7 -> 124 | K27: =+K16*K$7 -> 120 | M27: =+M16*M$7 -> 120 | N27: =+N16*N$7 -> 124 | O27: =SUM(C27:N27) -> 1336
A28: 4 | B28: Sirena Suites, Queen Bed (conecting) | C28: =+C17*C$7 -> 248 | D28: =+D17*D$7 -> 224 | E28: =+E17*E$7 -> 248 | F28: =+F17*F$7 -> 240 | G28: =+G17*G$7 -> 248 | H28: =+H17*H$7 -> 240 | I28: =+I17*I$7 -> 248 | J28: =+J17*J$7 -> 248 | K28: =+K17*K$7 -> 240 | M28: =+M17*M$7 -> 240 | N28: =+N17*N$7 -> 248 | O28: =SUM(C28:N28) -> 2672
A29: 5 | B29: Treehouse king bed | C29: =+C18*C$7 -> 155 | D29: =+D18*D$7 -> 140 | E29: =+E18*E$7 -> 155 | F29: =+F18*F$7 -> 150 | G29: =+G18*G$7 -> 155 | H29: =+H18*H$7 -> 150 | I29: =+I18*I$7 -> 155 | J29: =+J18*J$7 -> 155 | K29: =+K18*K$7 -> 150 | M29: =+M18*M$7 -> 150 | N29: =+N18*N$7 -> 155 | O29: =SUM(C29:N29) -> 1670
A30: 6 | B30: 5 Elements Treehouse king bed | C30: =+C19*C$7 -> 155 | D30: =+D19*D$7 -> 140 | E30: =+E19*E$7 -> 155 | F30: =+F19*F$7 -> 150 | G30: =+G19*G$7 -> 155 | H30: =+H19*H$7 -> 150 | I30: =+I19*I$7 -> 155 | J30: =+J19*J$7 -> 155 | K30: =+K19*K$7 -> 150 | M30: =+M19*M$7 -> 150 | N30: =+N19*N$7 -> 155 | O30: =SUM(C30:N30) -> 1670
B32: Total | C32: =SUM(C25:C31) -> 930 | D32: =SUM(D25:D31) -> 840 | E32: =SUM(E25:E31) -> 930 | F32: =SUM(F25:F31) -> 900 | G32: =SUM(G25:G31) -> 930 | H32: =SUM(H25:H31) -> 900 | I32: =SUM(I25:I31) -> 930 | J32: =SUM(J25:J31) -> 930 | ... O32: =SUM(O25:O31) -> 10020
B35: Rack Rates Rooms only | R35: Rack Rates Rooms only
B37: Room Type | C37: January | D37: February | E37: March | F37: April | G37: May | H37: June | I37: July | J37: August | K37: September | L37: October | M37: November | N37: December | R37: Room Type | S37: January | T37: February | U37: March | V37: April | W37: May | X37: June | Y37: July | Z37: August | AA37: September | AB37: October | AC37: November | AD37: December
A38: 1 | B38: Corcovado Deluxe Villas, King bed | C38: 725 | D38: 725 | E38: 725 | F38: 725 | G38: 615 | H38: 615 | I38: 615 | J38: 615 | K38: 560 | L38: 560 | M38: 575 | N38: 830 | R38: Corcovado Deluxe Villas, King bed | S38: 525 | T38: 525 | U38: 525 | V38: 505 | W38: 455 | X38: 440 | Y38: 440 | Z38: 440 | AA38: 405 | AB38: 395 | AC38: 415 | AD38: 575
A39: 2 | B39: Carate Deluxe Villa Double Beds | C39: 670 | D39: 670 | E39: 670 | F39: 635 | G39: 565 | H39: 565 | I39: 565 | J39: 565 | K39: 515 | L39: 515 | M39: 535 | N39: 775 | R39: Carate Deluxe Villa Double Beds | S39: 485 | T39: 485 | U39: 485 | V39: 460 | W39: 435 | X39: 420 | Y39: 420 | Z39: 420 | AA39: 395 | AB39: 375 | AC39: 440 | AD39: 520
A40: 3 | B40: Agujas Villa 2 Queen Beds | C40: 540 | D40: 540 | E40: 540 | F40: 510 | G40: 445 | H40: 445 | I40: 445 | J40: 445 | K40: 405 | L40: 405 | M40: 415 | N40: 630 | R40: Agujas Villa 2 Queen Beds | S40: 445 | T40: 445 | U40: 445 | V40: 415 | W40: 395 | X40: 375 | Y40: 375 | Z40: 375 | AA40: 355 | AB40: 330 | AC40: 360 | AD40: 485
A41: 4 | B41: Sirena Suites, Queen Bed (conecting) | C41: 485 | D41: 485 | E41: 485 | F41: 445 | G41: 395 | H41: 395 | I41: 395 | J41: 395 | K41: 360 | L41: 360 | M41: 375 | N41: 575 | R41: Sirena Suites, Queen Bed (conecting) | S41: 395 | T41: 395 | U41: 395 | V41: 360 | W41: 330 | X41: 315 | Y41: 315 | Z41: 315 | AA41: 290 | AB41: 275 | AC41: 295 | AD41: 410
A42: 5 | B42: Treehouse king bed | C42: 1015 | D42: 1015 | E42: 1015 | F42: 970 | G42: 875 | H42: 875 | I42: 875 | J42: 875 | K42: 810 | L42: 810 | M42: 845 | N42: 1150 | R42: Treehouse king bed | S42: 795 | T42: 795 | U42: 795 | V42: 725 | W42: 655 | X42: 620 | Y42: 620 | Z42: 620 | AA42: 585 | AB42: 530 | AC42: 605 | AD42: 785
A43: 6 | B43: 5 Elements Treehouse king bed | C43: 1130 | D43: 1130 | E43: 1130 | F43: 1065 | G43: 980 | H43: 980 | I43: 980 | J43: 980 | K43: 910 | L43: 910 | M43: 965 | N43: 1282 | R43: 5 Elements Treehouse king bed | S43: 895 | T43: 895 | U43: 895 | V43: 830 | W43: 740 | X43: 685 | Y43: 685 | Z43: 685 | AA43: 630 | AB43: 605 | AC43: 685 | AD43: 895
B47: NET RATE | Q47: =+#REF!/#REF! -> #REF! | AE47: 500
AE48: =+#REF!/AE47 -> #REF!
B50: Occupancy
B51: Room Type | C51: January | D51: February | E51: March | F51: April | G51: May | H51: June | I51: July | J51: August | K51: September | L51: October | M51: November | N51: December | O51: TOTAL | AE51: 650
B52: Corcovado Deluxe Villas, King bed | C52: 606.1 | D52: 606.1 | E52: 606.1 | F52: 606.1 | G52: 514.14 | H52: 514.14 | I52: 514.14 | J52: 514.14 | K52: 468.16 | M52: 480.7 | N52: 693.88 | O52: 589.6608
B53: Carate Deluxe Villa Double Beds | C53: 560.12 | D53: 560.12 | E53: 560.12 | F53: 530.86 | G53: 472.34 | H53: 472.34 | I53: 472.34 | J53: 472.34 | K53: 430.54 | M53: 447.26 | N53: 647.9 | O53: 537.62728 | AE53: 676.41
B54: Agujas Villa 2 Queen Beds | C54: 451.44 | D54: 451.44 | E54: 451.44 | F54: 426.36 | G54: 372.02 | H54: 372.02 | I54: 372.02 | J54: 372.02 | K54: 338.58 | M54: 346.94 | N54: 526.68 | O54: 431.54041
B55: Sirena Suites, Queen Bed (conecting) | C55: 405.46 | D55: 405.46 | E55: 405.46 | F55: 372.02 | G55: 330.22 | H55: 330.22 | I55: 330.22 | J55: 330.22 | M55: 313.5 | N55: 480.7 | O55: 388.71626
B56: Treehouse king bed | C56: 848.54 | D56: 848.54 | E56: 848.54 | F56: 810.92 | G56: 731.5 | H56: 731.5 | I56: 731.5 | J56: 731.5 | M56: 706.42 | N56: 961.4 | O56: 806.34693
B57: 5 Elements Treehouse king bed | C57: 944.68 | D57: 944.68 | E57: 944.68 | F57: 890.34 | G57: 819.28 | H57: 819.28 | I57: 819.28 | J57: 819.28 | M57: 806.74 | N57: 1071.752 | O57: 909.38828
B58: TOTAL | C58: 595.27155 | D58: 583.47405 | E58: 590.96203 | F58: 635.29075 | G58: 521.40328 | H58: 553.7017 | I58: 566.23141 | J58: 520.6179 | K58: 485.58682 | M58: 548.40744 | N58: 733.76344 | O58: 596.88852

Sheet Key Indicators
C4: 46023 | D4: 46024 | E4: 46025 | F4: 46026 | G4: 46027 | H4: 46028 | I4: 46029 | J4: 46030 | K4: 46031 | L4: 46032 | M4: 46033 | N4: 46034
B6: Units Available | C6: 30 | D6: 30 | E6: 30 | F6: 30 | G6: 30 | H6: 30 | I6: 30 | J6: 30 | K6: 30 | L6: 30 | M6: 30 | N6: 30
B7: Day per month | C7: 31 | D7: 28 | E7: 31 | F7: 30 | G7: 31 | H7: 30 | I7: 31 | J7: 31 | K7: 30 | L7: 31 | M7: 30 | N7: 31
B9: Total Nights Available | C9: =+C6*C7 -> 930 | D9: =+D6*D7 -> 840 | E9: =+E6*E7 -> 930 | F9: =+F6*F7 -> 900 | G9: =+G6*G7 -> 930 | H9: =+H6*H7 -> 900 | I9: =+I6*I7 -> 930 | J9: =+J6*J7 -> 930 | ... N9: =+N6*N7 -> 930
B12: Units Category
A14: 1 | B14: Corcovado Deluxe Villas, King bed | C14: 6 | D14: 6 | E14: 6 | F14: 6 | G14: 6 | H14: 6 | I14: 6 | J14: 6 | K14: 6 | L14: 6 | M14: 6 | N14: 6
A15: 2 | B15: Carate Deluxe Villa Double Beds | C15: 2 | D15: 2 | E15: 2 | F15: 2 | G15: 2 | H15: 2 | I15: 2 | J15: 2 | K15: 2 | L15: 2 | M15: 2 | N15: 2
A16: 3 | B16: Agujas Villa 2 Queen Beds | C16: 4 | D16: 4 | E16: 4 | F16: 4 | G16: 4 | H16: 4 | I16: 4 | J16: 4 | K16: 4 | L16: 4 | M16: 4 | N16: 4
A17: 4 | B17: Sirena Suites, Queen Bed (conecting) | C17: 8 | D17: 8 | E17: 8 | F17: 8 | G17: 8 | H17: 8 | I17: 8 | J17: 8 | K17: 8 | L17: 8 | M17: 8 | N17: 8
A18: 5 | B18: Treehouse king bed | C18: 5 | D18: 5 | E18: 5 | F18: 5 | G18: 5 | H18: 5 | I18: 5 | J18: 5 | K18: 5 | L18: 5 | M18: 5 | N18: 5
A19: 6 | B19: 5 Elements Treehouse king bed | C19: 5 | D19: 5 | E19: 5 | F19: 5 | G19: 5 | H19: 5 | I19: 5 | J19: 5 | K19: 5 | L19: 5 | M19: 5 | N19: 5
B20: Total | C20: =SUM(C14:C19) -> 30 | D20: =SUM(D14:D19) -> 30 | E20: =SUM(E14:E19) -> 30 | F20: =SUM(F14:F19) -> 30 | G20: =SUM(G14:G19) -> 30 | H20: =SUM(H14:H19) -> 30 | I20: =SUM(I14:I19) -> 30 | J20: =SUM(J14:J19) -> 30 | ... N20: =SUM(N14:N19) -> 30
B23: Total Room Nights Available per Category
A25: 1 | B25: Corcovado Deluxe Villas, King bed | C25: =+C14*C$7 -> 186 | D25: =+D14*D$7 -> 168 | E25: =+E14*E$7 -> 186 | F25: =+F14*F$7 -> 180 | G25: =+G14*G$7 -> 186 | H25: =+H14*H$7 -> 180 | I25: =+I14*I$7 -> 186 | J25: =+J14*J$7 -> 186 | K25: =+K14*K$7 -> 180 | M25: =+M14*M$7 -> 180 | N25: =+N14*N$7 -> 186 | O25: =SUM(C25:N25) -> 2004
A26: 2 | B26: Carate Deluxe Villa Double Beds | C26: =+C15*C$7 -> 62 | D26: =+D15*D$7 -> 56 | E26: =+E15*E$7 -> 62 | F26: =+F15*F$7 -> 60 | G26: =+G15*G$7 -> 62 | H26: =+H15*H$7 -> 60 | I26: =+I15*I$7 -> 62 | J26: =+J15*J$7 -> 62 | K26: =+K15*K$7 -> 60 | M26: =+M15*M$7 -> 60 | N26: =+N15*N$7 -> 62 | O26: =SUM(C26:N26) -> 668
A27: 3 | B27: Agujas Villa 2 Queen Beds | C27: =+C16*C$7 -> 124 | D27: =+D16*D$7 -> 112 | E27: =+E16*E$7 -> 124 | F27: =+F16*F$7 -> 120 | G27: =+G16*G$7 -> 124 | H27: =+H16*H$7 -> 120 | I27: =+I16*I$7 -> 124 | J27: =+J16*J$7 -> 124 | K27: =+K16*K$7 -> 120 | M27: =+M16*M$7 -> 120 | N27: =+N16*N$7 -> 124 | O27: =SUM(C27:N27) -> 1336
A28: 4 | B28: Sirena Suites, Queen Bed (conecting) | C28: =+C17*C$7 -> 248 | D28: =+D17*D$7 -> 224 | E28: =+E17*E$7 -> 248 | F28: =+F17*F$7 -> 240 | G28: =+G17*G$7 -> 248 | H28: =+H17*H$7 -> 240 | I28: =+I17*I$7 -> 248 | J28: =+J17*J$7 -> 248 | K28: =+K17*K$7 -> 240 | M28: =+M17*M$7 -> 240 | N28: =+N17*N$7 -> 248 | O28: =SUM(C28:N28) -> 2672
A29: 5 | B29: Treehouse king bed | C29: =+C18*C$7 -> 155 | D29: =+D18*D$7 -> 140 | E29: =+E18*E$7 -> 155 | F29: =+F18*F$7 -> 150 | G29: =+G18*G$7 -> 155 | H29: =+H18*H$7 -> 150 | I29: =+I18*I$7 -> 155 | J29: =+J18*J$7 -> 155 | K29: =+K18*K$7 -> 150 | M29: =+M18*M$7 -> 150 | N29: =+N18*N$7 -> 155 | O29: =SUM(C29:N29) -> 1670
A30: 6 | B30: 5 Elements Treehouse king bed | C30: =+C19*C$7 -> 155 | D30: =+D19*D$7 -> 140 | E30: =+E19*E$7 -> 155 | F30: =+F19*F$7 -> 150 | G30: =+G19*G$7 -> 155 | H30: =+H19*H$7 -> 150 | I30: =+I19*I$7 -> 155 | J30: =+J19*J$7 -> 155 | K30: =+K19*K$7 -> 150 | M30: =+M19*M$7 -> 150 | N30: =+N19*N$7 -> 155 | O30: =SUM(C30:N30) -> 1670
B32: Total | C32: =SUM(C25:C31) -> 930 | D32: =SUM(D25:D31) -> 840 | E32: =SUM(E25:E31) -> 930 | F32: =SUM(F25:F31) -> 900 | G32: =SUM(G25:G31) -> 930 | H32: =SUM(H25:H31) -> 900 | I32: =SUM(I25:I31) -> 930 | J32: =SUM(J25:J31) -> 930 | ... O32: =SUM(O25:O31) -> 10020
B35: Rack Rates Rooms only | R35: Rack Rates Rooms only
B37: Room Type | C37: January | D37: February | E37: March | F37: April | G37: May | H37: June | I37: July | J37: August | K37: September | L37: October | M37: November | N37: December | R37: Room Type | S37: January | T37: February | U37: March | V37: April | W37: May | X37: June | Y37: July | Z37: August | AA37: September | AB37: October | AC37: November | AD37: December
A38: 1 | B38: Corcovado Deluxe Villas, King bed | C38: 725 | D38: 725 | E38: 725 | F38: 725 | G38: 615 | H38: 615 | I38: 615 | J38: 615 | K38: 560 | L38: 560 | M38: 575 | N38: 830 | R38: Corcovado Deluxe Villas, King bed | S38: 525 | T38: 525 | U38: 525 | V38: 505 | W38: 455 | X38: 440 | Y38: 440 | Z38: 440 | AA38: 405 | AB38: 395 | AC38: 415 | AD38: 575
A39: 2 | B39: Carate Deluxe Villa Double Beds | C39: 670 | D39: 670 | E39: 670 | F39: 635 | G39: 565 | H39: 565 | I39: 565 | J39: 565 | K39: 515 | L39: 515 | M39: 535 | N39: 775 | R39: Carate Deluxe Villa Double Beds | S39: 485 | T39: 485 | U39: 485 | V39: 460 | W39: 435 | X39: 420 | Y39: 420 | Z39: 420 | AA39: 395 | AB39: 375 | AC39: 440 | AD39: 520
A40: 3 | B40: Agujas Villa 2 Queen Beds | C40: 540 | D40: 540 | E40: 540 | F40: 510 | G40: 445 | H40: 445 | I40: 445 | J40: 445 | K40: 405 | L40: 405 | M40: 415 | N40: 630 | R40: Agujas Villa 2 Queen Beds | S40: 445 | T40: 445 | U40: 445 | V40: 415 | W40: 395 | X40: 375 | Y40: 375 | Z40: 375 | AA40: 355 | AB40: 330 | AC40: 360 | AD40: 485
A41: 4 | B41: Sirena Suites, Queen Bed (conecting) | C41: 485 | D41: 485 | E41: 485 | F41: 445 | G41: 395 | H41: 395 | I41: 395 | J41: 395 | K41: 360 | L41: 360 | M41: 375 | N41: 575 | R41: Sirena Suites, Queen Bed (conecting) | S41: 395 | T41: 395 | U41: 395 | V41: 360 | W41: 330 | X41: 315 | Y41: 315 | Z41: 315 | AA41: 290 | AB41: 275 | AC41: 295 | AD41: 410
A42: 5 | B42: Treehouse king bed | C42: 1015 | D42: 1015 | E42: 1015 | F42: 970 | G42: 875 | H42: 875 | I42: 875 | J42: 875 | K42: 810 | L42: 810 | M42: 845 | N42: 1150 | R42: Treehouse king bed | S42: 795 | T42: 795 | U42: 795 | V42: 725 | W42: 655 | X42: 620 | Y42: 620 | Z42: 620 | AA42: 585 | AB42: 530 | AC42: 605 | AD42: 785
A43: 6 | B43: 5 Elements Treehouse king bed | C43: 1130 | D43: 1130 | E43: 1130 | F43: 1065 | G43: 980 | H43: 980 | I43: 980 | J43: 980 | K43: 910 | L43: 910 | M43: 965 | N43: 1282 | R43: 5 Elements Treehouse king bed | S43: 895 | T43: 895 | U43: 895 | V43: 830 | W43: 740 | X43: 685 | Y43: 685 | Z43: 685 | AA43: 630 | AB43: 605 | AC43: 685 | AD43: 895
B48: % of Sale by Channel | Q48: % of Sale by Channel today and Proforma
C49: =+C37 -> January | D49: =+D37 -> February | E49: =+E37 -> March | F49: =+F37 -> April | G49: =+G37 -> May | H49: =+H37 -> June | I49: =+I37 -> July | J49: =+J37 -> August | ... M49: =+M37 -> November | R49: Forecast 2025 | S49: Proforma
B50: Travel Agency | C50: 0.6 | D50: 0.6 | E50: 0.6 | F50: 0.6 | G50: 0.6 | H50: 0.6 | I50: 0.6 | J50: 0.6 | K50: 0.6 | L50: 0.6 | M50: 0.6 | Q50: Travel Agency | R50: 0.7 | S50: =+C50 -> 0.6
B51: OTAS | C51: 0.05 | D51: 0.05 | E51: 0.05 | F51: 0.05 | G51: 0.05 | H51: 0.05 | I51: 0.05 | J51: 0.05 | K51: 0.05 | L51: 0.05 | M51: 0.05 | Q51: OTAS | R51: 0.05 | S51: =+C51 -> 0.05
B52: DIRECT | C52: 0.35 | D52: 0.35 | E52: 0.35 | F52: 0.35 | G52: 0.35 | H52: 0.35 | I52: 0.35 | J52: 0.35 | K52: 0.35 | L52: 0.35 | M52: 0.35 | Q52: DIRECT | R52: 0.2 | S52: =+C52 -> 0.35
Q54: Commissions by Channel
B55: Total | C55: =SUM(C50:C54) -> 1 | D55: =SUM(D50:D54) -> 1 | E55: =SUM(E50:E54) -> 1 | F55: =SUM(F50:F54) -> 1 | G55: =SUM(G50:G54) -> 1 | H55: =SUM(H50:H54) -> 1 | I55: =SUM(I50:I54) -> 1 | J55: =SUM(J50:J54) -> 1 | ... M55: =SUM(M50:M54) -> 1
R56: Forecast 2025 | S56: Proforma
Q57: Travel Agency | R57: 0.28 | S57: =+M61 -> 0.28
Q58: OTAS | R58: 0.2 | S58: =+M62 -> 0.2
B59: COMMISSIONS By channel | Q59: DIRECT | R59: =+C63 -> 0 | S59: =+M63 -> 0
C60: =+C37 -> January | D60: =+D37 -> February | E60: =+E37 -> March | F60: =+F37 -> April | G60: =+G37 -> May | H60: =+H37 -> June | I60: =+I37 -> July | J60: =+J37 -> August | ... N60: =+N37 -> December
...

Sheet Key LIGIA (2)
C4: 46023 | D4: 46024 | E4: 46025 | F4: 46026 | G4: 46027 | H4: 46028 | I4: 46029 | J4: 46030 | K4: 46031 | L4: 46032 | M4: 46033 | N4: 46034
B6: Units Available | C6: 30 | D6: 30 | E6: 30 | F6: 30 | G6: 30 | H6: 30 | I6: 30 | J6: 30 | K6: 30 | L6: 30 | M6: 30 | N6: 30
B7: Day per month | C7: 31 | D7: 28 | E7: 31 | F7: 30 | G7: 31 | H7: 30 | I7: 31 | J7: 31 | K7: 30 | L7: 11 | M7: 30 | N7: 31
B9: Total Nights Available | C9: =+C6*C7 -> 930 | D9: =+D6*D7 -> 840 | E9: =+E6*E7 -> 930 | F9: =+F6*F7 -> 900 | G9: =+G6*G7 -> 930 | H9: =+H6*H7 -> 900 | I9: =+I6*I7 -> 930 | J9: =+J6*J7 -> 930 | ... N9: =+N6*N7 -> 930
B12: Units Category
A14: 1 | B14: Corcovado Deluxe Villas, King bed | C14: 6 | D14: 6 | E14: 6 | F14: 6 | G14: 6 | H14: 6 | I14: 6 | J14: 6 | K14: 6 | L14: 6 | M14: 6 | N14: 6
A15: 2 | B15: Carate Deluxe Villa Double Beds | C15: 2 | D15: 2 | E15: 2 | F15: 2 | G15: 2 | H15: 2 | I15: 2 | J15: 2 | K15: 2 | L15: 2 | M15: 2 | N15: 2
A16: 3 | B16: Agujas Villa 2 Queen Beds | C16: 3 | D16: 3 | E16: 3 | F16: 3 | G16: 3 | H16: 3 | I16: 3 | J16: 3 | K16: 3 | L16: 3 | M16: 3 | N16: 3
A17: 4 | B17: Sirena Suites, Queen Bed (conecting) | C17: 8 | D17: 8 | E17: 8 | F17: 8 | G17: 8 | H17: 8 | I17: 8 | J17: 8 | K17: 8 | L17: 8 | M17: 8 | N17: 8
A18: 5 | B18: Treehouse king bed | C18: 5 | D18: 5 | E18: 5 | F18: 5 | G18: 5 | H18: 5 | I18: 5 | J18: 5 | K18: 5 | L18: 5 | M18: 5 | N18: 5
A19: 6 | B19: 5 Elements Treehouse king bed | C19: 6 | D19: 6 | E19: 6 | F19: 6 | G19: 6 | H19: 6 | I19: 6 | J19: 6 | K19: 6 | L19: 6 | M19: 6 | N19: 6
B20: Total | C20: =SUM(C14:C19) -> 30 | D20: =SUM(D14:D19) -> 30 | E20: =SUM(E14:E19) -> 30 | F20: =SUM(F14:F19) -> 30 | G20: =SUM(G14:G19) -> 30 | H20: =SUM(H14:H19) -> 30 | I20: =SUM(I14:I19) -> 30 | J20: =SUM(J14:J19) -> 30 | ... N20: =SUM(N14:N19) -> 30
B23: Total Room Nights Available per Category
A25: 1 | B25: Corcovado Deluxe Villas, King bed | C25: =+C14*C$7 -> 186 | D25: =+D14*D$7 -> 168 | E25: =+E14*E$7 -> 186 | F25: =+F14*F$7 -> 180 | G25: =+G14*G$7 -> 186 | H25: =+H14*H$7 -> 180 | I25: =+I14*I$7 -> 186 | J25: =+J14*J$7 -> 186 | K25: =+K14*K$7 -> 180 | M25: =+M14*M$7 -> 180 | N25: =+N14*N$7 -> 186 | O25: =SUM(C25:N25) -> 2004
A26: 2 | B26: Carate Deluxe Villa Double Beds | C26: =+C15*C$7 -> 62 | D26: =+D15*D$7 -> 56 | E26: =+E15*E$7 -> 62 | F26: =+F15*F$7 -> 60 | G26: =+G15*G$7 -> 62 | H26: =+H15*H$7 -> 60 | I26: =+I15*I$7 -> 62 | J26: =+J15*J$7 -> 62 | K26: =+K15*K$7 -> 60 | M26: =+M15*M$7 -> 60 | N26: =+N15*N$7 -> 62 | O26: =SUM(C26:N26) -> 668
A27: 3 | B27: Agujas Villa 2 Queen Beds | C27: =+C16*C$7 -> 93 | D27: =+D16*D$7 -> 84 | E27: =+E16*E$7 -> 93 | F27: =+F16*F$7 -> 90 | G27: =+G16*G$7 -> 93 | H27: =+H16*H$7 -> 90 | I27: =+I16*I$7 -> 93 | J27: =+J16*J$7 -> 93 | K27: =+K16*K$7 -> 90 | M27: =+M16*M$7 -> 90 | N27: =+N16*N$7 -> 93 | O27: =SUM(C27:N27) -> 1002
A28: 4 | B28: Sirena Suites, Queen Bed (conecting) | C28: =+C17*C$7 -> 248 | D28: =+D17*D$7 -> 224 | E28: =+E17*E$7 -> 248 | F28: =+F17*F$7 -> 240 | G28: =+G17*G$7 -> 248 | H28: =+H17*H$7 -> 240 | I28: =+I17*I$7 -> 248 | J28: =+J17*J$7 -> 248 | K28: =+K17*K$7 -> 240 | M28: =+M17*M$7 -> 240 | N28: =+N17*N$7 -> 248 | O28: =SUM(C28:N28) -> 2672
A29: 5 | B29: Treehouse king bed | C29: =+C18*C$7 -> 155 | D29: =+D18*D$7 -> 140 | E29: =+E18*E$7 -> 155 | F29: =+F18*F$7 -> 150 | G29: =+G18*G$7 -> 155 | H29: =+H18*H$7 -> 150 | I29: =+I18*I$7 -> 155 | J29: =+J18*J$7 -> 155 | K29: =+K18*K$7 -> 150 | M29: =+M18*M$7 -> 150 | N29: =+N18*N$7 -> 155 | O29: =SUM(C29:N29) -> 1670
A30: 6 | B30: 5 Elements Treehouse king bed | C30: =+C19*C$7 -> 186 | D30: =+D19*D$7 -> 168 | E30: =+E19*E$7 -> 186 | F30: =+F19*F$7 -> 180 | G30: =+G19*G$7 -> 186 | H30: =+H19*H$7 -> 180 | I30: =+I19*I$7 -> 186 | J30: =+J19*J$7 -> 186 | K30: =+K19*K$7 -> 180 | M30: =+M19*M$7 -> 180 | N30: =+N19*N$7 -> 186 | O30: =SUM(C30:N30) -> 2004
B32: Total | C32: =SUM(C25:C31) -> 930 | D32: =SUM(D25:D31) -> 840 | E32: =SUM(E25:E31) -> 930 | F32: =SUM(F25:F31) -> 900 | G32: =SUM(G25:G31) -> 930 | H32: =SUM(H25:H31) -> 900 | I32: =SUM(I25:I31) -> 930 | J32: =SUM(J25:J31) -> 930 | ... O32: =SUM(O25:O31) -> 10020
B35: Rack Rates Rooms only | G35: LIGIA PUT IN THE 2026 RATES
B37: Room Type | C37: January | D37: February | E37: March | F37: April | G37: May | H37: June | I37: July | J37: August | K37: September | L37: October | M37: November | N37: December
A38: 1 | B38: Corcovado Deluxe Villas, King bed | C38: 725 | D38: 725 | E38: 725 | F38: 725 | G38: 615 | H38: 615 | I38: 615 | J38: 615 | K38: 560 | L38: 560 | M38: 575 | N38: 830
A39: 2 | B39: Carate Deluxe Villa Double Beds | C39: 670 | D39: 670 | E39: 670 | F39: 635 | G39: 565 | H39: 565 | I39: 565 | J39: 565 | K39: 515 | L39: 515 | M39: 535 | N39: 775
A40: 3 | B40: Agujas Villa 2 Queen Beds | C40: 540 | D40: 540 | E40: 540 | F40: 510 | G40: 445 | H40: 445 | I40: 445 | J40: 445 | K40: 405 | L40: 405 | M40: 415 | N40: 630
A41: 4 | B41: Sirena Suites, Queen Bed (conecting) | C41: 485 | D41: 485 | E41: 485 | F41: 445 | G41: 395 | H41: 395 | I41: 395 | J41: 395 | K41: 360 | L41: 360 | M41: 375 | N41: 575
A42: 5 | B42: Treehouse king bed | C42: 1015 | D42: 1015 | E42: 1015 | F42: 970 | G42: 875 | H42: 875 | I42: 875 | J42: 875 | K42: 810 | L42: 810 | M42: 845 | N42: 1150
A43: 6 | B43: 5 Elements Treehouse king bed | C43: 1130 | D43: 1130 | E43: 1130 | F43: 1065 | G43: 980 | H43: 980 | I43: 980 | J43: 980 | K43: 910 | L43: 910 | M43: 965 | N43: 1282
B48: % of Sale by Channel
C49: =+C37 -> January | D49: =+D37 -> February | E49: =+E37 -> March | F49: =+F37 -> April | G49: =+G37 -> May | H49: =+H37 -> June | I49: =+I37 -> July | J49: =+J37 -> August | ... M49: =+M37 -> November | N49: December
B50: Travel Agency | C50: 0.6 | D50: 0.6 | E50: 0.6 | F50: 0.55 | G50: 0.55 | H50: 0.55 | I50: 0.55 | J50: 0.55 | K50: 0.55 | L50: 0.55 | M50: 0.55 | N50: 0.55
B51: OTAS | C51: 0.05 | D51: 0.05 | E51: 0.05 | F51: 0.05 | G51: 0.05 | H51: 0.05 | I51: 0.05 | J51: 0.05 | K51: 0.05 | L51: 0.05 | M51: 0.05 | N51: 0.05
B52: DIRECT | C52: 0.35 | D52: 0.35 | E52: 0.35 | F52: 0.4 | G52: 0.4 | H52: 0.4 | I52: 0.4 | J52: 0.4 | K52: 0.4 | L52: 0.4 | M52: 0.4 | N52: 0.4
B53: NEW CHANNELS
B54: NEW CHANNELS
B56: Total | C56: =SUM(C50:C55) -> 1 | D56: =SUM(D50:D55) -> 1 | E56: =SUM(E50:E55) -> 1 | F56: =SUM(F50:F55) -> 1 | G56: =SUM(G50:G55) -> 1 | H56: =SUM(H50:H55) -> 1 | I56: =SUM(I50:I55) -> 1 | J56: =SUM(J50:J55) -> 1 | ... N56: =SUM(N50:N55) -> 1
B60: COMMISSIONS By channel
C61: =+C37 -> January
B62: Travel Agency | C62: 0.28
B63: OTAS | C63: 0.2
...

Sheet Key LIGIA
C4: 46023 | D4: 46024 | E4: 46025 | F4: 46026 | G4: 46027 | H4: 46028 | I4: 46029 | J4: 46030 | K4: 46031 | L4: 46032 | M4: 46033 | N4: 46034
B6: Units Available | C6: 30 | D6: 30 | E6: 30 | F6: 30 | G6: 30 | H6: 30 | I6: 30 | J6: 30 | K6: 30 | L6: 30 | M6: 30 | N6: 30
B7: Day per month | C7: 31 | D7: 28 | E7: 31 | F7: 30 | G7: 31 | H7: 30 | I7: 31 | J7: 31 | K7: 30 | L7: 31 | M7: 30 | N7: 31
B9: Total Nights Available | C9: =+C6*C7 -> 930 | D9: =+D6*D7 -> 840 | E9: =+E6*E7 -> 930 | F9: =+F6*F7 -> 900 | G9: =+G6*G7 -> 930 | H9: =+H6*H7 -> 900 | I9: =+I6*I7 -> 930 | J9: =+J6*J7 -> 930 | ... N9: =+N6*N7 -> 930
B12: Units Category
A14: 1 | B14: Corcovado Deluxe Villas, King bed | C14: 6 | D14: 6 | E14: 6 | F14: 6 | G14: 6 | H14: 6 | I14: 6 | J14: 6 | K14: 6 | L14: 6 | M14: 6 | N14: 6
A15: 2 | B15: Carate Deluxe Villa Double Beds | C15: 2 | D15: 2 | E15: 2 | F15: 2 | G15: 2 | H15: 2 | I15: 2 | J15: 2 | K15: 2 | L15: 2 | M15: 2 | N15: 2
A16: 3 | B16: Agujas Villa 2 Queen Beds | C16: 3 | D16: 3 | E16: 3 | F16: 3 | G16: 3 | H16: 3 | I16: 3 | J16: 3 | K16: 3 | L16: 3 | M16: 3 | N16: 3
A17: 4 | B17: Sirena Suites, Queen Bed (conecting) | C17: 8 | D17: 8 | E17: 8 | F17: 8 | G17: 8 | H17: 8 | I17: 8 | J17: 8 | K17: 8 | L17: 8 | M17: 8 | N17: 8
A18: 5 | B18: Treehouse king bed | C18: 5 | D18: 5 | E18: 5 | F18: 5 | G18: 5 | H18: 5 | I18: 5 | J18: 5 | K18: 5 | L18: 5 | M18: 5 | N18: 5
A19: 6 | B19: 5 Elements Treehouse king bed | C19: 6 | D19: 6 | E19: 6 | F19: 6 | G19: 6 | H19: 6 | I19: 6 | J19: 6 | K19: 6 | L19: 6 | M19: 6 | N19: 6
B20: Total | C20: =SUM(C14:C19) -> 30 | D20: =SUM(D14:D19) -> 30 | E20: =SUM(E14:E19) -> 30 | F20: =SUM(F14:F19) -> 30 | G20: =SUM(G14:G19) -> 30 | H20: =SUM(H14:H19) -> 30 | I20: =SUM(I14:I19) -> 30 | J20: =SUM(J14:J19) -> 30 | ... N20: =SUM(N14:N19) -> 30
B23: Total Room Nights Available per Category
A25: 1 | B25: Corcovado Deluxe Villas, King bed | C25: =+C14*C$7 -> 186 | D25: =+D14*D$7 -> 168 | E25: =+E14*E$7 -> 186 | F25: =+F14*F$7 -> 180 | G25: =+G14*G$7 -> 186 | H25: =+H14*H$7 -> 180 | I25: =+I14*I$7 -> 186 | J25: =+J14*J$7 -> 186 | ... N25: =+N14*N$7 -> 186 | O25: =SUM(C25:N25) -> 2190
A26: 2 | B26: Carate Deluxe Villa Double Beds | C26: =+C15*C$7 -> 62 | D26: =+D15*D$7 -> 56 | E26: =+E15*E$7 -> 62 | F26: =+F15*F$7 -> 60 | G26: =+G15*G$7 -> 62 | H26: =+H15*H$7 -> 60 | I26: =+I15*I$7 -> 62 | J26: =+J15*J$7 -> 62 | ... N26: =+N15*N$7 -> 62 | O26: =SUM(C26:N26) -> 730
A27: 3 | B27: Agujas Villa 2 Queen Beds | C27: =+C16*C$7 -> 93 | D27: =+D16*D$7 -> 84 | E27: =+E16*E$7 -> 93 | F27: =+F16*F$7 -> 90 | G27: =+G16*G$7 -> 93 | H27: =+H16*H$7 -> 90 | I27: =+I16*I$7 -> 93 | J27: =+J16*J$7 -> 93 | ... N27: =+N16*N$7 -> 93 | O27: =SUM(C27:N27) -> 1095
A28: 4 | B28: Sirena Suites, Queen Bed (conecting) | C28: =+C17*C$7 -> 248 | D28: =+D17*D$7 -> 224 | E28: =+E17*E$7 -> 248 | F28: =+F17*F$7 -> 240 | G28: =+G17*G$7 -> 248 | H28: =+H17*H$7 -> 240 | I28: =+I17*I$7 -> 248 | J28: =+J17*J$7 -> 248 | ... N28: =+N17*N$7 -> 248 | O28: =SUM(C28:N28) -> 2920
A29: 5 | B29: Treehouse king bed | C29: =+C18*C$7 -> 155 | D29: =+D18*D$7 -> 140 | E29: =+E18*E$7 -> 155 | F29: =+F18*F$7 -> 150 | G29: =+G18*G$7 -> 155 | H29: =+H18*H$7 -> 150 | I29: =+I18*I$7 -> 155 | J29: =+J18*J$7 -> 155 | ... N29: =+N18*N$7 -> 155 | O29: =SUM(C29:N29) -> 1825
A30: 6 | B30: 5 Elements Treehouse king bed | C30: =+C19*C$7 -> 186 | D30: =+D19*D$7 -> 168 | E30: =+E19*E$7 -> 186 | F30: =+F19*F$7 -> 180 | G30: =+G19*G$7 -> 186 | H30: =+H19*H$7 -> 180 | I30: =+I19*I$7 -> 186 | J30: =+J19*J$7 -> 186 | ... N30: =+N19*N$7 -> 186 | O30: =SUM(C30:N30) -> 2190
B32: Total | C32: =SUM(C25:C31) -> 930 | D32: =SUM(D25:D31) -> 840 | E32: =SUM(E25:E31) -> 930 | F32: =SUM(F25:F31) -> 900 | G32: =SUM(G25:G31) -> 930 | H32: =SUM(H25:H31) -> 900 | I32: =SUM(I25:I31) -> 930 | J32: =SUM(J25:J31) -> 930 | ... O32: =SUM(O25:O31) -> 10950
B35: Rack Rates Rooms only | G35: LIGIA PUT IN THE 2026 RATES
B37: Room Type | C37: January | D37: February | E37: March | F37: April | G37: May | H37: June | I37: July | J37: August | K37: September | L37: October | M37: November | N37: December
A38: 1 | B38: Corcovado Deluxe Villas, King bed | C38: =708.75/1.1 -> 644.31818 | D38: =708.75/1.1 -> 644.31818 | E38: =708.75/1.1 -> 644.31818 | F38: =681.75/1.1 -> 619.77273 | G38: =614.25/1.1 -> 558.40909 | H38: =594/1.1 -> 540 | I38: =594/1.1 -> 540 | J38: =594/1.1 -> 540 | K38: =546.75/1.1 -> 497.04545 | L38: =533.25/1.1 -> 484.77273 | M38: =560.25/1.1 -> 509.31818 | N38: =776.25/1.1 -> 705.68182
A39: 2 | B39: Carate Deluxe Villa Double Beds | C39: =654.75/1.1 -> 595.22727 | D39: =654.75/1.1 -> 595.22727 | E39: =654.75/1.1 -> 595.22727 | F39: =621/1.1 -> 564.54545 | G39: =587.25/1.1 -> 533.86364 | H39: =567/1.1 -> 515.45455 | I39: =567/1.1 -> 515.45455 | J39: =567/1.1 -> 515.45455 | K39: =533.25/1.1 -> 484.77273 | L39: =506.25/1.1 -> 460.22727 | M39: =594/1.1 -> 540 | N39: =702/1.1 -> 638.18182
A40: 3 | B40: Agujas Villa 2 Queen Beds | C40: =600.75/1.1 -> 546.13636 | D40: =600.75/1.1 -> 546.13636 | E40: =600.75/1.1 -> 546.13636 | F40: =560.25/1.1 -> 509.31818 | G40: =533.25/1.1 -> 484.77273 | H40: =506.25/1.1 -> 460.22727 | I40: =506.25/1.1 -> 460.22727 | J40: =506.25/1.1 -> 460.22727 | K40: =479.25/1.1 -> 435.68182 | L40: =445.5/1.1 -> 405 | M40: =486/1.1 -> 441.81818 | N40: =654.75/1.1 -> 595.22727
A41: 4 | B41: Sirena Suites, Queen Bed (conecting) | C41: =533.25/1.1 -> 484.77273 | D41: =533.25/1.1 -> 484.77273 | E41: =533.25/1.1 -> 484.77273 | F41: =486/1.1 -> 441.81818 | G41: =445.5/1.1 -> 405 | H41: =425.25/1.1 -> 386.59091 | I41: =425.25/1.1 -> 386.59091 | J41: =425.25/1.1 -> 386.59091 | K41: =391.5/1.1 -> 355.90909 | L41: =371.25/1.1 -> 337.5 | M41: =398.25/1.1 -> 362.04545 | N41: =553.5/1.1 -> 503.18182
A42: 5 | B42: Treehouse king bed | C42: =1073.25/1.1 -> 975.68182 | D42: =1073.25/1.1 -> 975.68182 | E42: =1073.25/1.1 -> 975.68182 | F42: =978.75/1.1 -> 889.77273 | G42: =884.25/1.1 -> 803.86364 | H42: =837/1.1 -> 760.90909 | I42: =837/1.1 -> 760.90909 | J42: =837/1.1 -> 760.90909 | K42: =789.75/1.1 -> 717.95455 | L42: =715.5/1.1 -> 650.45455 | M42: =816.75/1.1 -> 742.5 | N42: =1059.75/1.1 -> 963.40909
A43: 6 | B43: 5 Elements Treehouse king bed | C43: =1208.25/1.1 -> 1098.4091 | D43: =1208.25/1.1 -> 1098.4091 | E43: =1208.25/1.1 -> 1098.4091 | F43: =1120.5/1.1 -> 1018.6364 | G43: =999/1.1 -> 908.18182 | H43: =924.75/1.1 -> 840.68182 | I43: =924.75/1.1 -> 840.68182 | J43: =924.75/1.1 -> 840.68182 | K43: =850.5/1.1 -> 773.18182 | L43: =816.75/1.1 -> 742.5 | M43: =924.75/1.1 -> 840.68182 | N43: =1307.45/1.1 -> 1188.5909
B48: % of Sale by Channel
C49: =+C37 -> January | D49: =+D37 -> February | E49: =+E37 -> March | F49: =+F37 -> April | G49: =+G37 -> May | H49: =+H37 -> June | I49: =+I37 -> July | J49: =+J37 -> August | ... M49: =+M37 -> November
B50: Travel Agency | C50: 0.6 | D50: 0.6 | E50: 0.6 | F50: 0.6 | G50: 0.6 | H50: 0.6 | I50: 0.6 | J50: 0.6 | K50: 0.6 | L50: 0.6 | M50: 0.6
B51: OTAS | C51: 0.05 | D51: 0.05 | E51: 0.05 | F51: 0.05 | G51: 0.05 | H51: 0.05 | I51: 0.05 | J51: 0.05 | K51: 0.05 | L51: 0.05 | M51: 0.05
B52: DIRECT | C52: 0.35 | D52: 0.35 | E52: 0.35 | F52: 0.35 | G52: 0.35 | H52: 0.35 | I52: 0.35 | J52: 0.35 | K52: 0.35 | L52: 0.35 | M52: 0.35
B53: NEW CHANNELS
B54: NEW CHANNELS
B56: Total | C56: =SUM(C50:C55) -> 1 | D56: =SUM(D50:D55) -> 1 | E56: =SUM(E50:E55) -> 1 | F56: =SUM(F50:F55) -> 1 | G56: =SUM(G50:G55) -> 1 | H56: =SUM(H50:H55) -> 1 | I56: =SUM(I50:I55) -> 1 | J56: =SUM(J50:J55) -> 1 | ... M56: =SUM(M50:M55) -> 1
B60: COMMISSIONS By channel
C61: =+C37 -> January
B62: Travel Agency | C62: 0.28
B63: OTAS | C63: 0.2
...

Sheet Rooms
B1: ⟵ Back to Summary | D1: Rooms – Key Indicators & Budget
B11: Key Indicators 2024
B12: Indicator | C12: January | D12: February | E12: March | F12: April | G12: May | H12: June | I12: July | J12: August | K12: September | L12: October | M12: November | N12: December | O12: TOTAL | Q12: RATE
B13: Total available Rooms | C13: 930 | D13: 870 | E13: 930 | F13: 900 | G13: 930 | H13: 900 | I13: 930 | J13: 930 | K13: 900 | L13: 930 | M13: 900 | N13: 930 | O13: =SUM(C13:N13) -> 10980
B14: Total Rooms Occupied | C14: 429 | D14: 456 | E14: 448 | F14: 259 | G14: 176 | H14: 98 | I14: 249 | J14: 157 | K14: 6 | L14: 0 | M14: 179 | N14: 317 | O14: =SUM(C14:N14) -> 2774
B15: Total Guests | C15: 711 | D15: 834 | E15: 835 | F15: 544 | G15: 311 | H15: 160 | I15: 429 | J15: 310 | K15: 12 | M15: 316 | N15: 614 | O15: =SUM(C15:N15) -> 5076 | Q15: =+O15/O14 -> 1.8298486
B16: % Occupancy | C16: 0.4613 | D16: 0.5241 | E16: 0.4817 | F16: 0.2878 | G16: 0.1892 | H16: 0.1089 | I16: 0.2677 | J16: 0.1688 | K16: 0.0067 | M16: 0.1989 | N16: 0.3409 | O16: =+O14/O13 -> 0.25264117
B17: Average Daily Room Only | C17: =+C36/C14 -> 359.84047 | D17: =+D36/D14 -> 465.18852 | E17: =+E36/E14 -> 389.00314 | F17: =+F36/F14 -> 378.9522 | G17: =+G36/G14 -> 231.30814 | H17: =+H36/H14 -> 291.12236 | I17: =+I36/I14 -> 426.03102 | J17: =+J36/J14 -> 403.28888 | K17: =+K36/K14 -> 434.33013 | M17: =+M36/M14 -> 471.30737 | N17: =+N36/N14 -> 729.00372 | O17: =+O36/O14 -> 431.01011
B18: Key Indicators 2025
B19: Indicator | C19: January | D19: February | E19: March | F19: April | G19: May | H19: June | I19: July | J19: August | K19: September | L19: October | M19: November | N19: December | O19: TOTAL
B20: Total available Rooms | C20: 930 | D20: 840 | E20: 930 | F20: 900 | G20: 930 | H20: 900 | I20: 930 | J20: 930 | K20: 900 | L20: 930 | M20: 900 | N20: 930 | O20: =SUM(C20:N20) -> 10950
B21: Total Rooms Occupied | C21: 454 | D21: 479 | E21: 519 | F21: 239 | G21: 114 | H21: 102 | I21: 274 | J21: 220 | K21: 28 | L21: 50 | M21: 230 | N21: 470 | O21: =SUM(C21:N21) -> 3179
B22: Total Guests | C22: 809 | D22: 893 | E22: 962 | F22: 428 | G22: 228 | H22: 183 | I22: 611 | J22: 411 | K22: 27 | L22: 75 | M22: 345 | N22: 705 | O22: =SUM(C22:N22) -> 5677 | Q22: =+O22/O21 -> 1.7857817
B23: % Occupancy | C23: =+C21/C20 -> 0.48817204 | D23: =+D21/D20 -> 0.5702381 | E23: =+E21/E20 -> 0.55806452 | F23: =+F21/F20 -> 0.26555556 | G23: =+G21/G20 -> 0.12258065 | H23: =+H21/H20 -> 0.11333333 | I23: =+I21/I20 -> 0.29462366 | J23: =+J21/J20 -> 0.23655914 | ... O23: =+O21/O20 -> 0.29031963
B24: Average Daily Room Only | C24: =+C37/C21 -> 473.50649 | D24: =+D37/D21 -> 550.00104 | E24: =+E37/E21 -> 478.48852 | F24: =+F37/F21 -> 497.89901 | G24: =+G37/G21 -> 482.76039 | H24: =+H37/H21 -> 379.47717 | I24: =+I37/I21 -> 508.05451 | J24: =+J37/J21 -> 371.59366 | ... O24: =+O37/O21 -> 484.67682
B25: Key Indicators 2026 (Budget)
B26: Indicator | C26: January | D26: February | E26: March | F26: April | G26: May | H26: June | I26: July | J26: August | K26: September | L26: October | M26: November | N26: December | O26: TOTAL
B27: Total available Rooms | C27: =+'Key Indicators'!C318 -> 930 | D27: =+'Key Indicators'!D318 -> 840 | E27: =+'Key Indicators'!E318 -> 930 | F27: =+'Key Indicators'!F318 -> 900 | G27: =+'Key Indicators'!G318 -> 930 | H27: =+'Key Indicators'!H318 -> 900 | I27: =+'Key Indicators'!I318 -> 930 | J27: =+'Key Indicators'!J318 -> 930 | ... N27: =+'Key Indicators'!N318 -> 930 | O27: =SUM(C27:N27) -> 10020
B28: Total Rooms Occupied | C28: =+'Key Indicators'!C319 -> 697.5 | D28: =+'Key Indicators'!D319 -> 638.4 | E28: =+'Key Indicators'!E319 -> 607.7 | F28: =+'Key Indicators'!F319 -> 332 | G28: =+'Key Indicators'!G319 -> 232.48621 | H28: =+'Key Indicators'!H319 -> 167.65517 | I28: =+'Key Indicators'!I319 -> 332.1 | J28: =+'Key Indicators'!J319 -> 251.32 | ... N28: =+'Key Indicators'!N319 -> 611.7075 | O28: =SUM(C28:N28) -> 4363.2889
B29: Total Guests | C29: =+'Key Indicators'!C320 -> 1255.5 | D29: =+'Key Indicators'!D320 -> 1149.12 | E29: =+'Key Indicators'!E320 -> 1093.86 | F29: =+'Key Indicators'!F320 -> 597.6 | G29: =+'Key Indicators'!G320 -> 418.47517 | H29: =+'Key Indicators'!H320 -> 301.77931 | I29: =+'Key Indicators'!I320 -> 597.78 | J29: =+'Key Indicators'!J320 -> 452.376 | ... N29: =+'Key Indicators'!N320 -> 1101.0735 | O29: =SUM(C29:N29) -> 7853.92 | Q29: =+O29/O28 -> 1.8
B30: % Occupancy | C30: =+C28/C27 -> 0.75 | D30: =+D28/D27 -> 0.76 | E30: =+E28/E27 -> 0.65344086 | F30: =+F28/F27 -> 0.36888889 | G30: =+G28/G27 -> 0.24998517 | H30: =+H28/H27 -> 0.18628352 | I30: =+I28/I27 -> 0.35709677 | J30: =+J28/J27 -> 0.27023656 | K30: =+K28/K27 -> 0.091466667 | M30: =+M28/M27 -> 0.45566667 | N30: =+N28/N27 -> 0.65775 | O30: =+O28/O27 -> 0.43545797
B31: Average Daily Room Only | C31: =+C38/C28 -> 595.27155 | D31: =+D38/D28 -> 583.47405 | E31: =+E38/E28 -> 590.96203 | F31: =+F38/F28 -> 635.29075 | G31: =+G38/G28 -> 521.40328 | H31: =+H38/H28 -> 553.7017 | I31: =+I38/I28 -> 566.23141 | J31: =+J38/J28 -> 520.6179 | K31: =+K38/K28 -> 485.58682 | M31: =+M38/M28 -> 548.40744 | N31: =+N38/N28 -> 733.76344 | O31: =+O38/O28 -> 596.88852
B34: Revenue by Monthper Year
B35: Label | C35: January | D35: February | E35: March | F35: April | G35: May | H35: June | I35: July | J35: August | K35: September | L35: October | M35: November | N35: December | O35: TOTAL
B36: Revenue 2024 | C36: 154371.56 | D36: 212125.96 | E36: 174273.41 | F36: 98148.619 | G36: 40710.232 | H36: 28529.992 | I36: 106081.72 | J36: 63316.354 | K36: 2605.9808 | L36: 0 | M36: 84364.018 | N36: 231094.18 | O36: =SUM(C36:N36) -> 1195622
B37: Revenue 2025 | C37: 214971.95 | D37: 263450.5 | E37: 248335.54 | F37: 118997.86 | G37: 55034.684 | H37: 38706.671 | I37: 139206.94 | J37: 81750.604 | K37: 11282.86 | L37: 19750 | M37: 93150 | N37: 256150 | O37: =SUM(C37:N37) -> 1540787.6
B38: Revenue 2026 Budget | C38: =+'Key Indicators'!C327 -> 415201.91 | D38: =+'Key Indicators'!D327 -> 372489.83 | E38: =+'Key Indicators'!E327 -> 359127.63 | F38: =+'Key Indicators'!F327 -> 210916.53 | G38: =+'Key Indicators'!G327 -> 121219.07 | H38: =+'Key Indicators'!H327 -> 92830.953 | I38: =+'Key Indicators'!I327 -> 188045.45 | J38: =+'Key Indicators'!J327 -> 130841.69 | ... N38: =+'Key Indicators'!N327 -> 448848.6 | O38: =SUM(C38:N38) -> 2604397.1
B41: Increase from 2025 to 2026 RN | C41: =(C38-C37)/C37 -> 0.93142368 | D41: =(D38-D37)/D37 -> 0.41388926 | E41: =(E38-E37)/E37 -> 0.44613867 | F41: =(F38-F37)/F37 -> 0.77243964 | G41: =(G38-G37)/G37 -> 1.2025941 | H41: =(H38-H37)/H37 -> 1.3983192 | I41: =(I38-I37)/I37 -> 0.35083391 | J41: =(J38-J37)/J37 -> 0.60049815 | ... O41: =(O38-O37)/O37 -> 0.69030244
B42: Increase from 2025 to 2026 Rev | C42: =+C38-C37 -> 200229.96 | D42: =+D38-D37 -> 109039.33 | E42: =+E38-E37 -> 110792.09 | F42: =+F38-F37 -> 91918.667 | G42: =+G38-G37 -> 66184.386 | H42: =+H38-H37 -> 54124.282 | I42: =+I38-I37 -> 48838.514 | J42: =+J38-J37 -> 49091.087 | ... O42: =+O38-O37 -> 1063609.4

Sheet Food Revenue
B1: ⟵ Back to Summary | D1: Food Revenue – Key Indicators & Budget
B11: Key Indicators 2024
B12: Indicator | C12: January | D12: February | E12: March | F12: April | G12: May | H12: June | I12: July | J12: August | K12: September | L12: October | M12: November | N12: December | O12: TOTAL
B13: Total available Rooms | C13: =Rooms!C13 -> 930 | D13: =Rooms!D13 -> 870 | E13: =Rooms!E13 -> 930 | F13: =Rooms!F13 -> 900 | G13: =Rooms!G13 -> 930 | H13: =Rooms!H13 -> 900 | I13: =Rooms!I13 -> 930 | J13: =Rooms!J13 -> 930 | ... O13: =Rooms!O13 -> 10980
B14: Total Rooms Occupied | C14: =Rooms!C14 -> 429 | D14: =Rooms!D14 -> 456 | E14: =Rooms!E14 -> 448 | F14: =Rooms!F14 -> 259 | G14: =Rooms!G14 -> 176 | H14: =Rooms!H14 -> 98 | I14: =Rooms!I14 -> 249 | J14: =Rooms!J14 -> 157 | ... O14: =Rooms!O14 -> 2774
B15: Total Guests | C15: =Rooms!C15 -> 711 | D15: =Rooms!D15 -> 834 | E15: =Rooms!E15 -> 835 | F15: =Rooms!F15 -> 544 | G15: =Rooms!G15 -> 311 | H15: =Rooms!H15 -> 160 | I15: =Rooms!I15 -> 429 | J15: =Rooms!J15 -> 310 | ... O15: =Rooms!O15 -> 5076
B16: % Occupancy | C16: =Rooms!C16 -> 0.4613 | D16: =Rooms!D16 -> 0.5241 | E16: =Rooms!E16 -> 0.4817 | F16: =Rooms!F16 -> 0.2878 | G16: =Rooms!G16 -> 0.1892 | H16: =Rooms!H16 -> 0.1089 | I16: =Rooms!I16 -> 0.2677 | J16: =Rooms!J16 -> 0.1688 | ... O16: =Rooms!O16 -> 0.25264117
B17: Average Daily Room Only | C17: =Rooms!C17 -> 359.84047 | D17: =Rooms!D17 -> 465.18852 | E17: =Rooms!E17 -> 389.00314 | F17: =Rooms!F17 -> 378.9522 | G17: =Rooms!G17 -> 231.30814 | H17: =Rooms!H17 -> 291.12236 | I17: =Rooms!I17 -> 426.03102 | J17: =Rooms!J17 -> 403.28888 | ... O17: =Rooms!O17 -> 431.01011
B18: Key Indicators 2025
B19: Indicator | C19: January | D19: February | E19: March | F19: April | G19: May | H19: June | I19: July | J19: August | K19: September | L19: October | M19: November | N19: December | O19: TOTAL
B20: Total available Rooms | C20: =Rooms!C20 -> 930 | D20: =Rooms!D20 -> 840 | E20: =Rooms!E20 -> 930 | F20: =Rooms!F20 -> 900 | G20: =Rooms!G20 -> 930 | H20: =Rooms!H20 -> 900 | I20: =Rooms!I20 -> 930 | J20: =Rooms!J20 -> 930 | ... O20: =Rooms!O20 -> 10950
B21: Total Rooms Occupied | C21: =Rooms!C21 -> 454 | D21: =Rooms!D21 -> 479 | E21: =Rooms!E21 -> 519 | F21: =Rooms!F21 -> 239 | G21: =Rooms!G21 -> 114 | H21: =Rooms!H21 -> 102 | I21: =Rooms!I21 -> 274 | J21: =Rooms!J21 -> 220 | ... O21: =Rooms!O21 -> 3179
B22: Total Guests | C22: =Rooms!C22 -> 809 | D22: =Rooms!D22 -> 893 | E22: =Rooms!E22 -> 962 | F22: =Rooms!F22 -> 428 | G22: =Rooms!G22 -> 228 | H22: =Rooms!H22 -> 183 | I22: =Rooms!I22 -> 611 | J22: =Rooms!J22 -> 411 | ... O22: =Rooms!O22 -> 5677
B23: % Occupancy | C23: =Rooms!C23 -> 0.48817204 | D23: =Rooms!D23 -> 0.5702381 | E23: =Rooms!E23 -> 0.55806452 | F23: =Rooms!F23 -> 0.26555556 | G23: =Rooms!G23 -> 0.12258065 | H23: =Rooms!H23 -> 0.11333333 | I23: =Rooms!I23 -> 0.29462366 | J23: =Rooms!J23 -> 0.23655914 | ... O23: =Rooms!O23 -> 0.29031963
B24: Average Daily Room Only | C24: =Rooms!C24 -> 473.50649 | D24: =Rooms!D24 -> 550.00104 | E24: =Rooms!E24 -> 478.48852 | F24: =Rooms!F24 -> 497.89901 | G24: =Rooms!G24 -> 482.76039 | H24: =Rooms!H24 -> 379.47717 | I24: =Rooms!I24 -> 508.05451 | J24: =Rooms!J24 -> 371.59366 | ... O24: =Rooms!O24 -> 484.67682
B25: Key Indicators 2026 (Budget)
B26: Indicator | C26: January | D26: February | E26: March | F26: April | G26: May | H26: June | I26: July | J26: August | K26: September | L26: October | M26: November | N26: December | O26: TOTAL
B27: Total available Rooms | C27: =Rooms!C27 -> 930 | D27: =Rooms!D27 -> 840 | E27: =Rooms!E27 -> 930 | F27: =Rooms!F27 -> 900 | G27: =Rooms!G27 -> 930 | H27: =Rooms!H27 -> 900 | I27: =Rooms!I27 -> 930 | J27: =Rooms!J27 -> 930 | ... O27: =Rooms!O27 -> 10020
B28: Total Rooms Occupied | C28: =Rooms!C28 -> 697.5 | D28: =Rooms!D28 -> 638.4 | E28: =Rooms!E28 -> 607.7 | F28: =Rooms!F28 -> 332 | G28: =Rooms!G28 -> 232.48621 | H28: =Rooms!H28 -> 167.65517 | I28: =Rooms!I28 -> 332.1 | J28: =Rooms!J28 -> 251.32 | ... O28: =Rooms!O28 -> 4363.2889
B29: Total Guests | C29: =Rooms!C29 -> 1255.5 | D29: =Rooms!D29 -> 1149.12 | E29: =Rooms!E29 -> 1093.86 | F29: =Rooms!F29 -> 597.6 | G29: =Rooms!G29 -> 418.47517 | H29: =Rooms!H29 -> 301.77931 | I29: =Rooms!I29 -> 597.78 | J29: =Rooms!J29 -> 452.376 | ... O29: =Rooms!O29 -> 7853.92
B30: % Occupancy | C30: =Rooms!C30 -> 0.75 | D30: =Rooms!D30 -> 0.76 | E30: =Rooms!E30 -> 0.65344086 | F30: =Rooms!F30 -> 0.36888889 | G30: =Rooms!G30 -> 0.24998517 | H30: =Rooms!H30 -> 0.18628352 | I30: =Rooms!I30 -> 0.35709677 | J30: =Rooms!J30 -> 0.27023656 | ... O30: =Rooms!O30 -> 0.43545797
B31: Average Daily Room Only | C31: =Rooms!C31 -> 595.27155 | D31: =Rooms!D31 -> 583.47405 | E31: =Rooms!E31 -> 590.96203 | F31: =Rooms!F31 -> 635.29075 | G31: =Rooms!G31 -> 521.40328 | H31: =Rooms!H31 -> 553.7017 | I31: =Rooms!I31 -> 566.23141 | J31: =Rooms!J31 -> 520.6179 | ... O31: =Rooms!O31 -> 596.88852
B34: Revenue by Month
B35: Label | C35: January | D35: February | E35: March | F35: April | G35: May | H35: June | I35: July | J35: August | K35: September | L35: October | M35: November | N35: December | O35: TOTAL
B36: Revenue 2024 | C36: 40539.559 | D36: 51930.053 | E36: 51479.405 | F36: 31261.324 | G36: 12340.602 | H36: 10377.842 | I36: 27201.505 | J36: 20146.528 | K36: 879.44131 | L36: 0 | M36: 23570.483 | N36: 48192.13 | O36: =SUM(C36:N36) -> 317918.87
B37: Revenue 2025 | C37: 55354.294 | D37: 72196.172 | E37: 70786.323 | F37: 36330.097 | G37: 16129.355 | H37: 13689.425 | I37: 46042.427 | J37: 26588.885 | K37: 6403.05 | L37: 0 | M37: 29454.03 | N37: 55066.23 | O37: =SUM(C37:N37) -> 428040.29
